Using Theano backend.
/home/y00752450/anaconda2/lib/python2.7/site-packages/flask/exthook.py:71: ExtDeprecationWarning: Importing flask.ext.cors is deprecated, use flask_cors instead.
  .format(x=modname), ExtDeprecationWarning
 * Running on http://0.0.0.0:5000/ (Press CTRL+C to quit)
 * Restarting with stat
Using Theano backend.
/home/y00752450/anaconda2/lib/python2.7/site-packages/flask/exthook.py:71: ExtDeprecationWarning: Importing flask.ext.cors is deprecated, use flask_cors instead.
  .format(x=modname), ExtDeprecationWarning
 * Debugger is active!
 * Debugger pin code: 223-517-525
Using Theano backend.
/home/y00752450/anaconda2/lib/python2.7/site-packages/flask/exthook.py:71: ExtDeprecationWarning: Importing flask.ext.cors is deprecated, use flask_cors instead.
  .format(x=modname), ExtDeprecationWarning
 * Running on http://0.0.0.0:5000/ (Press CTRL+C to quit)
 * Restarting with stat
Using Theano backend.
/home/y00752450/anaconda2/lib/python2.7/site-packages/flask/exthook.py:71: ExtDeprecationWarning: Importing flask.ext.cors is deprecated, use flask_cors instead.
  .format(x=modname), ExtDeprecationWarning
 * Debugger is active!
 * Debugger pin code: 223-517-525
 * Detected change in '/home/y00752450/anaconda2/lib/python2.7/site-packages/numpy/core/info.py', reloading
Using Theano backend.
/home/y00752450/anaconda2/lib/python2.7/site-packages/flask/exthook.py:71: ExtDeprecationWarning: Importing flask.ext.cors is deprecated, use flask_cors instead.
  .format(x=modname), ExtDeprecationWarning
 * Running on http://0.0.0.0:5000/ (Press CTRL+C to quit)
 * Restarting with stat
Using Theano backend.
/home/y00752450/anaconda2/lib/python2.7/site-packages/flask/exthook.py:71: ExtDeprecationWarning: Importing flask.ext.cors is deprecated, use flask_cors instead.
  .format(x=modname), ExtDeprecationWarning
 * Debugger is active!
 * Debugger pin code: 223-517-525
58.247.119.41 - - [06/Jul/2016 11:54:07] "OPTIONS /api/data/fileList HTTP/1.1" 200 -
58.247.119.41 - - [06/Jul/2016 11:54:07] "OPTIONS /api/data/defaultConf HTTP/1.1" 200 -
58.247.119.41 - - [06/Jul/2016 11:54:18] "POST /api/data/fileList HTTP/1.1" 200 -
58.247.119.41 - - [06/Jul/2016 11:54:18] "POST /api/data/defaultConf HTTP/1.1" 200 -
58.247.119.41 - - [06/Jul/2016 11:54:18] "OPTIONS /api/data/fileList HTTP/1.1" 200 -
58.247.119.41 - - [06/Jul/2016 11:54:18] "OPTIONS /api/data/defaultConf HTTP/1.1" 200 -
58.247.119.41 - - [06/Jul/2016 11:54:19] "POST /api/data/fileList HTTP/1.1" 200 -
58.247.119.41 - - [06/Jul/2016 11:54:19] "POST /api/data/defaultConf HTTP/1.1" 200 -
58.247.119.41 - - [06/Jul/2016 11:54:37] "OPTIONS /api/execution HTTP/1.1" 200 -
58.247.119.41 - - [06/Jul/2016 11:54:37] "GET /api/data/reportList?testSet=3G_150821_1w.csv&trainSet=3G_150820_1w.csv HTTP/1.1" 200 -
INFO - ALG_RF_roc_expt - Running command 'start'
INFO - ALG_RF_roc_expt - Started
ERROR - ALG_RF_roc_expt - Failed after 0:00:00!
58.247.119.41 - - [06/Jul/2016 11:54:37] "POST /api/execution HTTP/1.1" 500 -
INFO - werkzeug - 58.247.119.41 - - [06/Jul/2016 11:54:37] "POST /api/execution HTTP/1.1" 500 -
Traceback (most recent call last):
  File "/home/y00752450/anaconda2/lib/python2.7/site-packages/flask/app.py", line 2000, in __call__
    return self.wsgi_app(environ, start_response)
  File "/home/y00752450/anaconda2/lib/python2.7/site-packages/flask/app.py", line 1991, in wsgi_app
    response = self.make_response(self.handle_exception(e))
  File "/home/y00752450/anaconda2/lib/python2.7/site-packages/flask_cors/extension.py", line 188, in wrapped_function
    return cors_after_request(app.make_response(f(*args, **kwargs)))
  File "/home/y00752450/anaconda2/lib/python2.7/site-packages/flask/app.py", line 1567, in handle_exception
    reraise(exc_type, exc_value, tb)
  File "/home/y00752450/anaconda2/lib/python2.7/site-packages/flask/app.py", line 1988, in wsgi_app
    response = self.full_dispatch_request()
  File "/home/y00752450/anaconda2/lib/python2.7/site-packages/flask/app.py", line 1641, in full_dispatch_request
    rv = self.handle_user_exception(e)
  File "/home/y00752450/anaconda2/lib/python2.7/site-packages/flask_cors/extension.py", line 188, in wrapped_function
    return cors_after_request(app.make_response(f(*args, **kwargs)))
  File "/home/y00752450/anaconda2/lib/python2.7/site-packages/flask/app.py", line 1544, in handle_user_exception
    reraise(exc_type, exc_value, tb)
  File "/home/y00752450/anaconda2/lib/python2.7/site-packages/flask/app.py", line 1639, in full_dispatch_request
    rv = self.dispatch_request()
  File "/home/y00752450/anaconda2/lib/python2.7/site-packages/flask/app.py", line 1625, in dispatch_request
    return self.view_functions[rule.endpoint](**req.view_args)
  File "/home/y00752450/TelData-LocVis/back-end/index.py", line 241, in runAlgorithm
    res = Algorithms[id].run().result
  File "/home/y00752450/anaconda2/lib/python2.7/site-packages/sacred/experiment.py", line 109, in run
    named_configs=named_configs)
  File "/home/y00752450/anaconda2/lib/python2.7/site-packages/sacred/experiment.py", line 137, in run_command
    run()
  File "/home/y00752450/anaconda2/lib/python2.7/site-packages/sacred/run.py", line 146, in __call__
    self.result = self.main_function(*args)
  File "/home/y00752450/anaconda2/lib/python2.7/site-packages/sacred/config/captured_function.py", line 47, in captured_function
    result = wrapped(*args, **kwargs)
  File "/home/y00752450/TelData-LocVis/back-end/localization/algorithms/RF_roc/alg_RF_roc.py", line 347, in start
    res = run(trainPath,testPath,etui.matchGC(trainSet),configuration,outPath)
  File "/home/y00752450/TelData-LocVis/back-end/localization/algorithms/RF_roc/alg_RF_roc.py", line 196, in run
    gongcan = pd.read_csv(gcpath)
  File "/home/y00752450/anaconda2/lib/python2.7/site-packages/pandas/io/parsers.py", line 529, in parser_f
    return _read(filepath_or_buffer, kwds)
  File "/home/y00752450/anaconda2/lib/python2.7/site-packages/pandas/io/parsers.py", line 295, in _read
    parser = TextFileReader(filepath_or_buffer, **kwds)
  File "/home/y00752450/anaconda2/lib/python2.7/site-packages/pandas/io/parsers.py", line 612, in __init__
    self._make_engine(self.engine)
  File "/home/y00752450/anaconda2/lib/python2.7/site-packages/pandas/io/parsers.py", line 747, in _make_engine
    self._engine = CParserWrapper(self.f, **self.options)
  File "/home/y00752450/anaconda2/lib/python2.7/site-packages/pandas/io/parsers.py", line 1119, in __init__
    self._reader = _parser.TextReader(src, **kwds)
  File "pandas/parser.pyx", line 353, in pandas.parser.TextReader.__cinit__ (pandas/parser.c:3246)
    
  File "pandas/parser.pyx", line 591, in pandas.parser.TextReader._setup_parser_source (pandas/parser.c:6111)
    
IOError: File data/3G_gongcan.csv does not exist
